<sdf version='1.7'>
  <model name='gopigo3'>
    <link name='base_footprint'>
      <inertial>
        <pose>-0.023176 0 0.039614 0 -0 0</pose>
        <mass>0.932</mass>
        <inertia>
          <ixx>0.00402406</ixx>
          <ixy>-0.000156</ixy>
          <ixz>0.000101343</ixz>
          <iyy>0.00749146</iyy>
          <iyz>-0.000223</iyz>
          <izz>0.0053554</izz>
        </inertia>
      </inertial>
      <collision name='base_footprint_fixed_joint_lump__base_link_collision'>
        <pose>-0.038 0 0 0 -0 0</pose>
        <geometry>
          <box>
            <size>0.245 0.088 0.02</size>
          </box>
        </geometry>
        <surface>
          <contact>
            <ode/>
          </contact>
          <friction>
            <ode/>
          </friction>
        </surface>
      </collision>
      <collision name='base_footprint_fixed_joint_lump__camera_link_collision_1'>
        <pose>0.075 0 0.043 0 -0 0</pose>
        <geometry>
          <box>
            <size>0.015 0.03 0.027</size>
          </box>
        </geometry>
        <surface>
          <contact>
            <ode/>
          </contact>
          <friction>
            <ode/>
          </friction>
        </surface>
      </collision>
      <collision name='base_footprint_fixed_joint_lump__name_link_collision_2'>
        <pose>-0.115 0 0.057 0 -0 0</pose>
        <geometry>
          <box>
            <size>0.01 0.01 0.002</size>
          </box>
        </geometry>
        <surface>
          <contact>
            <ode/>
          </contact>
          <friction>
            <ode/>
          </friction>
        </surface>
      </collision>
      <collision name='base_footprint_fixed_joint_lump__base_scan_collision_3'>
        <pose>0 0 0.14 0 -0 0</pose>
        <geometry>
          <cylinder>
            <length>0.055</length>
            <radius>0.035</radius>
          </cylinder>
        </geometry>
        <surface>
          <contact>
            <ode/>
          </contact>
          <friction>
            <ode/>
          </friction>
        </surface>
      </collision>
      <visual name='base_footprint_fixed_joint_lump__base_link_visual'>
        <pose>0 0 0 0 -0 0</pose>
        <geometry>
          <mesh>
            <scale>0.0012 0.0012 0.0012</scale>
            <uri>model://robot_description/meshes/GoPiGo3_Body90.obj</uri>
          </mesh>
        </geometry>
        <material>
          <script>
            <name>Gazebo/GreenTransparent</name>
            <uri>file://media/materials/scripts/gazebo.material</uri>
          </script>
        </material>
      </visual>
      <visual name='base_footprint_fixed_joint_lump__camera_link_visual_1'>
        <pose>0.07 0 0.03 0 1.5708 0</pose>
        <geometry>
          <mesh>
            <scale>0.00125 0.00125 0.00125</scale>
            <uri>model://robot_description/meshes/piCamera.stl</uri>
          </mesh>
        </geometry>
        <material>
          <script>
            <name>Gazebo/Red</name>
            <uri>file://media/materials/scripts/gazebo.material</uri>
          </script>
        </material>
      </visual>
      <visual name='base_footprint_fixed_joint_lump__name_link_visual_2'>
        <pose>-0.115 0 0.057 0 -0 0</pose>
        <geometry>
          <mesh>
            <scale>0.0008 0.0008 0.0008</scale>
            <uri>model://robot_description/meshes/number2.stl</uri>
          </mesh>
        </geometry>
        <material>
          <script>
            <name>Gazebo/Yellow</name>
            <uri>file://media/materials/scripts/gazebo.material</uri>
          </script>
        </material>
      </visual>
      <visual name='base_footprint_fixed_joint_lump__base_scan_visual_3'>
        <pose>0.005 0 0.14 0 -0 0</pose>
        <geometry>
          <mesh>
            <scale>0.001 0.001 0.001</scale>
            <uri>model://robot_description/meshes/Lidar.stl</uri>
          </mesh>
        </geometry>
        <material>
          <script>
            <name>Gazebo/Blue</name>
            <uri>file://media/materials/scripts/gazebo.material</uri>
          </script>
        </material>
      </visual>
      <sensor name='camera1' type='camera'>
        <always_on>1</always_on>
        <visualize>0</visualize>
        <camera name='front'>
          <horizontal_fov>1.39626</horizontal_fov>
          <image>
            <width>800</width>
            <height>800</height>
            <format>R8G8B8</format>
          </image>
          <clip>
            <near>0.02</near>
            <far>300</far>
          </clip>
        </camera>
        <plugin name='camera_controller' filename='libgazebo_ros_camera.so'>
          <alwaysOn>1</alwaysOn>
          <updateRate>30.0</updateRate>
          <cameraName>gopigo/camera1</cameraName>
          <imageTopicName>image_raw</imageTopicName>
          <cameraInfoTopicName>camera_info</cameraInfoTopicName>
          <frameName>camera_rgb_frame</frameName>
          <hackBaseline>0.07</hackBaseline>
          <distortionK1>0.0</distortionK1>
          <distortionK2>0.0</distortionK2>
          <distortionK3>0.0</distortionK3>
          <distortionT1>0.0</distortionT1>
          <distortionT2>0.0</distortionT2>
        </plugin>
        <pose>0.07 0 0.03 0 -0 0</pose>
      </sensor>
      <sensor name='lds_lfcd_sensor' type='ray'>
        <visualize>0</visualize>
        <update_rate>10</update_rate>
        <ray>
          <scan>
            <horizontal>
              <samples>720</samples>
              <resolution>1</resolution>
              <min_angle>0</min_angle>
              <max_angle>6.28319</max_angle>
            </horizontal>
          </scan>
          <range>
            <min>0.12</min>
            <max>10</max>
            <resolution>0.015</resolution>
          </range>
          <noise>
            <type>gaussian</type>
            <mean>0</mean>
            <stddev>0.02</stddev>
          </noise>
        </ray>
        <plugin name='gazebo_ros_lds_lfcd_controller' filename='libgazebo_ros_laser.so'>
          <topicName>scan</topicName>
          <frameName>base_scan</frameName>
        </plugin>
        <pose>0 0 0.14 0 -0 0</pose>
      </sensor>
    </link>
    <joint name='wheel_left_joint' type='revolute'>
      <pose relative_to='base_footprint'>0 0.058 0 0 -0 1.57</pose>
      <parent>base_footprint</parent>
      <child>wheel_left_link</child>
      <axis>
        <xyz>1 0 0</xyz>
        <limit>
          <lower>-1e+16</lower>
          <upper>1e+16</upper>
        </limit>
        <dynamics>
          <spring_reference>0</spring_reference>
          <spring_stiffness>0</spring_stiffness>
        </dynamics>
      </axis>
    </joint>
    <link name='wheel_left_link'>
      <pose relative_to='wheel_left_joint'>0 0 0 0 -0 0</pose>
      <inertial>
        <pose>0 0 0 0 -0 0</pose>
        <mass>0.032</mass>
        <inertia>
          <ixx>1.74e-05</ixx>
          <ixy>0</ixy>
          <ixz>0</ixz>
          <iyy>1.05e-05</iyy>
          <iyz>0</iyz>
          <izz>1.05e-05</izz>
        </inertia>
      </inertial>
      <collision name='wheel_left_link_collision'>
        <pose>0 0 0 0 1.5708 0</pose>
        <geometry>
          <cylinder>
            <length>0.026</length>
            <radius>0.033</radius>
          </cylinder>
        </geometry>
        <surface>
          <contact>
            <ode>
              <kp>500000</kp>
              <kd>10</kd>
              <max_vel>0.5</max_vel>
              <min_depth>0.001</min_depth>
            </ode>
          </contact>
          <friction>
            <ode>
              <mu>0.5</mu>
              <mu2>0.5</mu2>
              <fdir1>1 0 0</fdir1>
            </ode>
          </friction>
        </surface>
      </collision>
      <visual name='wheel_left_link_visual'>
        <pose>-0.22581 -0.200334 -0.033582 0 -0 0</pose>
        <geometry>
          <mesh>
            <scale>0.001158 0.001158 0.001158</scale>
            <uri>model://robot_description/meshes/GoPiGo3_Wheel.stl</uri>
          </mesh>
        </geometry>
        <material>
          <script>
            <name>Gazebo/FlatBlack</name>
            <uri>file://media/materials/scripts/gazebo.material</uri>
          </script>
        </material>
      </visual>
    </link>
    <joint name='wheel_right_joint' type='revolute'>
      <pose relative_to='base_footprint'>0 -0.058 0 0 0 -1.57</pose>
      <parent>base_footprint</parent>
      <child>wheel_right_link</child>
      <axis>
        <xyz>-1 0 0</xyz>
        <limit>
          <lower>-1e+16</lower>
          <upper>1e+16</upper>
        </limit>
        <dynamics>
          <spring_reference>0</spring_reference>
          <spring_stiffness>0</spring_stiffness>
        </dynamics>
      </axis>
    </joint>
    <link name='wheel_right_link'>
      <pose relative_to='wheel_right_joint'>0 0 0 0 -0 0</pose>
      <inertial>
        <pose>0 0 0 0 -0 0</pose>
        <mass>0.032</mass>
        <inertia>
          <ixx>1.74e-05</ixx>
          <ixy>0</ixy>
          <ixz>0</ixz>
          <iyy>1.05e-05</iyy>
          <iyz>0</iyz>
          <izz>1.05e-05</izz>
        </inertia>
      </inertial>
      <collision name='wheel_right_link_collision'>
        <pose>0 0 0 0 1.5708 0</pose>
        <geometry>
          <cylinder>
            <length>0.026</length>
            <radius>0.033</radius>
          </cylinder>
        </geometry>
        <surface>
          <contact>
            <ode>
              <kp>500000</kp>
              <kd>10</kd>
              <max_vel>0.5</max_vel>
              <min_depth>0.001</min_depth>
            </ode>
          </contact>
          <friction>
            <ode>
              <mu>0.5</mu>
              <mu2>0.5</mu2>
              <fdir1>1 0 0</fdir1>
            </ode>
          </friction>
        </surface>
      </collision>
      <visual name='wheel_right_link_visual'>
        <pose>-0.22581 -0.200334 -0.033582 0 -0 0</pose>
        <geometry>
          <mesh>
            <scale>0.001158 0.001158 0.001158</scale>
            <uri>model://robot_description/meshes/GoPiGo3_Wheel.stl</uri>
          </mesh>
        </geometry>
        <material>
          <script>
            <name>Gazebo/FlatBlack</name>
            <uri>file://media/materials/scripts/gazebo.material</uri>
          </script>
        </material>
      </visual>
    </link>
    <static>0</static>
    <plugin name='gopigo3_controller' filename='libgazebo_ros_diff_drive.so'>
      <commandTopic>cmd_vel</commandTopic>
      <odometryTopic>odom</odometryTopic>
      <odometryFrame>odom</odometryFrame>
      <odometrySource>world</odometrySource>
      <publishOdomTF>1</publishOdomTF>
      <robotBaseFrame>base_footprint</robotBaseFrame>
      <publishWheelTF>0</publishWheelTF>
      <publishTf>1</publishTf>
      <publishWheelJointState>1</publishWheelJointState>
      <legacyMode>0</legacyMode>
      <updateRate>30</updateRate>
      <leftJoint>wheel_left_joint</leftJoint>
      <rightJoint>wheel_right_joint</rightJoint>
      <wheelSeparation>0.116</wheelSeparation>
      <wheelDiameter>0.066</wheelDiameter>
      <wheelAcceleration>0.5</wheelAcceleration>
      <wheelTorque>1</wheelTorque>
      <rosDebugLevel>na</rosDebugLevel>
    </plugin>
  </model>
</sdf>
