<?xml version='1.0'?>
<robot name="gpgMin">

  <!-- Base Link -->
  <link name="base_link">
    <visual>
      <origin xyz="0 0 0" rpy="0 0 0" />
      <geometry>
          <box size="0.22 0.104 0.070"/>
      </geometry>
      <material name="blue">
        <color rgba="0 0.5 1 0.5"/>
      </material>
    </visual>

    <!-- Caster -->
    <visual name="caster">
      <origin xyz="-0.1 0 -0.0575" rpy="0 0 0" />
      <geometry>
        <sphere radius="0.01" />
      </geometry>
    </visual>
  </link>

  <!-- Right Wheel -->
  <link name="right_wheel">
    <visual>
      <origin xyz="0 0 0" rpy="1.570795 0 0" />
      <geometry>
          <cylinder length="0.025" radius="0.0325" />
      </geometry>
      <material name="black">
        <color rgba="0.05 0.05 0.05 0.5"/>
      </material>
    </visual>
  </link>

  <joint name="joint_right_wheel" type="continuous">
    <parent link="base_link"/>
    <child link="right_wheel"/>
    <origin xyz="0.020 -0.058 -0.035" rpy="0 0 0" /> 
    <axis xyz="0 1 0" />
  </joint>

  <!-- Left Wheel -->
  <link name="left_wheel">
    <visual>
      <origin xyz="0 0 0" rpy="1.570795 0 0" />
      <geometry>
          <cylinder length="0.025" radius="0.0325" />
      </geometry>
      <material name="black"/>
    </visual>
  </link>
  
  <joint name="joint_left_wheel" type="continuous">
    <parent link="base_link"/>
    <child link="left_wheel"/>
    <origin xyz="0.020 0.058 -0.035" rpy="0 0 0" /> 
    <axis xyz="0 1 0" />
  </joint>

</robot>
